Workbook

Sheet Dashboard
A1: Bank of Baroda Statement Analysis
A3: Period Covered | B3: Apr 2026 to Apr 2026 | I3: Period | J3: Receipts | K3: Payments | L3: Net | M3: Closing Balance | N3: Checks
A4: Statements Reviewed | B4: 1 | I4: ='Monthly Summary'!D2 | J4: ='Monthly Summary'!J2 | K4: ='Monthly Summary'!I2 | L4: =ROUND(J4-K4,2) | M4: ='Monthly Summary'!K2 | N4: ='Monthly Summary'!N2&"/"&'Monthly Summary'!O2
A5: Transactions Parsed | B5: 398
A7: Total Receipts | B7: ='Category Summary'!D2
A8: Total Payments | B8: ='Category Summary'!F2
A9: Net Movement | B9: =ROUND('Category Summary'!G2,2)
A10: Cash Receipts | B10: ='Category Summary'!D3
A11: High Transaction Value | B11: =ROUND('Category Summary'!D7-'Category Summary'!F7,2)
A12: Recurring Transaction Value | B12: =ROUND('Category Summary'!D4-'Category Summary'!F4,2)
A13: UPI / LIC / EMI / Salary | B13: =ROUND('Category Summary'!G8+'Category Summary'!G9+'Category Summary'!G5+'Category Summary'!G6,2)
A15: Category | B15: Receipt Count | C15: Receipts | D15: Payment Count | E15: Payments | F15: Net | G15: Action / View Detail
A16: ='Category Summary'!A2 | B16: ='Category Summary'!C2 | C16: ='Category Summary'!D2 | D16: ='Category Summary'!E2 | E16: ='Category Summary'!F2 | F16: ='Category Summary'!G2
A17: ='Category Summary'!A3 | B17: ='Category Summary'!C3 | C17: ='Category Summary'!D3 | D17: ='Category Summary'!E3 | E17: ='Category Summary'!F3 | F17: ='Category Summary'!G3
A18: ='Category Summary'!A4 | B18: ='Category Summary'!C4 | C18: ='Category Summary'!D4 | D18: ='Category Summary'!E4 | E18: ='Category Summary'!F4 | F18: ='Category Summary'!G4
A19: ='Category Summary'!A5 | B19: ='Category Summary'!C5 | C19: ='Category Summary'!D5 | D19: ='Category Summary'!E5 | E19: ='Category Summary'!F5 | F19: ='Category Summary'!G5
A20: ='Category Summary'!A6 | B20: ='Category Summary'!C6 | C20: ='Category Summary'!D6 | D20: ='Category Summary'!E6 | E20: ='Category Summary'!F6 | F20: ='Category Summary'!G6
A21: ='Category Summary'!A7 | B21: ='Category Summary'!C7 | C21: ='Category Summary'!D7 | D21: ='Category Summary'!E7 | E21: ='Category Summary'!F7 | F21: ='Category Summary'!G7
A22: ='Category Summary'!A8 | B22: ='Category Summary'!C8 | C22: ='Category Summary'!D8 | D22: ='Category Summary'!E8 | E22: ='Category Summary'!F8 | F22: ='Category Summary'!G8
A23: ='Category Summary'!A9 | B23: ='Category Summary'!C9 | C23: ='Category Summary'!D9 | D23: ='Category Summary'!E9 | E23: ='Category Summary'!F9 | F23: ='Category Summary'!G9
A24: ='Category Summary'!A10 | B24: ='Category Summary'!C10 | C24: ='Category Summary'!D10 | D24: ='Category Summary'!E10 | E24: ='Category Summary'!F10 | F24: ='Category Summary'!G10
A25: ='Category Summary'!A11 | B25: ='Category Summary'!C11 | C25: ='Category Summary'!D11 | D25: ='Category Summary'!E11 | E25: ='Category Summary'!F11 | F25: ='Category Summary'!G11
A26: ='Category Summary'!A12 | B26: ='Category Summary'!C12 | C26: ='Category Summary'!D12 | D26: ='Category Summary'!E12 | E26: ='Category Summary'!F12 | F26: ='Category Summary'!G12

Sheet Category Summary
A1: Requested Category | B1: Match Term | C1: Receipt Count | D1: Receipts | E1: Payment Count | F1: Payments | G1: Net | H1: Notes
A2: Total | C2: =COUNTIF(Transactions!$I$2:$I$399,"Receipt") | D2: =SUM(Transactions!$K$2:$K$399) | E2: =COUNTIF(Transactions!$I$2:$I$399,"Payment") | F2: =SUM(Transactions!$J$2:$J$399) | G2: =ROUND(D2-F2,2) | H2: All parsed receipts and payments.
A3: Cash | B3: Cash | C3: =COUNTIFS(Transactions!$Q$2:$Q$399,1,Transactions!$I$2:$I$399,"Receipt") | D3: =SUMIFS(Transactions!$K$2:$K$399,Transactions!$Q$2:$Q$399,1) | E3: =COUNTIFS(Transactions!$Q$2:$Q$399,1,Transactions!$I$2:$I$399,"Payment") | F3: =SUMIFS(Transactions!$J$2:$J$399,Transactions!$Q$2:$Q$399,1) | G3: =ROUND(D3-F3,2) | H3: Cash detected from CASH DEPOSIT BY narration.
A4: Recurring Transaction | B4: Recurring Transaction | C4: =COUNTIFS(Transactions!$R$2:$R$399,1,Transactions!$I$2:$I$399,"Receipt") | D4: =SUMIFS(Transactions!$K$2:$K$399,Transactions!$R$2:$R$399,1) | E4: =COUNTIFS(Transactions!$R$2:$R$399,1,Transactions!$I$2:$I$399,"Payment") | F4: =SUMIFS(Transactions!$J$2:$J$399,Transactions!$R$2:$R$399,1) | G4: =ROUND(D4-F4,2) | H4: Repeated counterpart/pattern appearing at least twice.
A5: EMI | B5: EMI | C5: =COUNTIFS(Transactions!$S$2:$S$399,1,Transactions!$I$2:$I$399,"Receipt") | D5: =SUMIFS(Transactions!$K$2:$K$399,Transactions!$S$2:$S$399,1) | E5: =COUNTIFS(Transactions!$S$2:$S$399,1,Transactions!$I$2:$I$399,"Payment") | F5: =SUMIFS(Transactions!$J$2:$J$399,Transactions!$S$2:$S$399,1) | G5: =ROUND(D5-F5,2) | H5: Keyword based: EMI/ECS/ACH/loan/installment.
A6: Salary | B6: Salary | C6: =COUNTIFS(Transactions!$T$2:$T$399,1,Transactions!$I$2:$I$399,"Receipt") | D6: =SUMIFS(Transactions!$K$2:$K$399,Transactions!$T$2:$T$399,1) | E6: =COUNTIFS(Transactions!$T$2:$T$399,1,Transactions!$I$2:$I$399,"Payment") | F6: =SUMIFS(Transactions!$J$2:$J$399,Transactions!$T$2:$T$399,1) | G6: =ROUND(D6-F6,2) | H6: Keyword based: salary.
A7: High Transaction | B7: High Transaction | C7: =COUNTIFS(Transactions!$U$2:$U$399,1,Transactions!$I$2:$I$399,"Receipt") | D7: =SUMIFS(Transactions!$K$2:$K$399,Transactions!$U$2:$U$399,1) | E7: =COUNTIFS(Transactions!$U$2:$U$399,1,Transactions!$I$2:$I$399,"Payment") | F7: =SUMIFS(Transactions!$J$2:$J$399,Transactions!$U$2:$U$399,1) | G7: =ROUND(D7-F7,2) | H7: Transactions with absolute amount at or above Rs 100,000.
A8: UPI | B8: UPI | C8: =COUNTIFS(Transactions!$V$2:$V$399,1,Transactions!$I$2:$I$399,"Receipt") | D8: =SUMIFS(Transactions!$K$2:$K$399,Transactions!$V$2:$V$399,1) | E8: =COUNTIFS(Transactions!$V$2:$V$399,1,Transactions!$I$2:$I$399,"Payment") | F8: =SUMIFS(Transactions!$J$2:$J$399,Transactions!$V$2:$V$399,1) | G8: =ROUND(D8-F8,2) | H8: Keyword based: UPI.
A9: LIC | B9: LIC | C9: =COUNTIFS(Transactions!$W$2:$W$399,1,Transactions!$I$2:$I$399,"Receipt") | D9: =SUMIFS(Transactions!$K$2:$K$399,Transactions!$W$2:$W$399,1) | E9: =COUNTIFS(Transactions!$W$2:$W$399,1,Transactions!$I$2:$I$399,"Payment") | F9: =SUMIFS(Transactions!$J$2:$J$399,Transactions!$W$2:$W$399,1) | G9: =ROUND(D9-F9,2) | H9: Keyword based: LIC.
A10: FD interest | B10: FD interest | C10: =COUNTIFS(Transactions!$X$2:$X$399,1,Transactions!$I$2:$I$399,"Receipt") | D10: =SUMIFS(Transactions!$K$2:$K$399,Transactions!$X$2:$X$399,1) | E10: =COUNTIFS(Transactions!$X$2:$X$399,1,Transactions!$I$2:$I$399,"Payment") | F10: =SUMIFS(Transactions!$J$2:$J$399,Transactions!$X$2:$X$399,1) | G10: =ROUND(D10-F10,2) | H10: Keyword based: FD plus interest/int.
A11: FD Deposit and withdrawals | B11: FD Deposit/Withdrawal | C11: =COUNTIFS(Transactions!$Y$2:$Y$399,1,Transactions!$I$2:$I$399,"Receipt") | D11: =SUMIFS(Transactions!$K$2:$K$399,Transactions!$Y$2:$Y$399,1) | E11: =COUNTIFS(Transactions!$Y$2:$Y$399,1,Transactions!$I$2:$I$399,"Payment") | F11: =SUMIFS(Transactions!$J$2:$J$399,Transactions!$Y$2:$Y$399,1) | G11: =ROUND(D11-F11,2) | H11: Keyword based: FD/fixed deposit/TDR/term deposit.
A12: PPF/PF interest and contribution | B12: PPF/PF interest/contribution | C12: =COUNTIFS(Transactions!$Z$2:$Z$399,1,Transactions!$I$2:$I$399,"Receipt") | D12: =SUMIFS(Transactions!$K$2:$K$399,Transactions!$Z$2:$Z$399,1) | E12: =COUNTIFS(Transactions!$Z$2:$Z$399,1,Transactions!$I$2:$I$399,"Payment") | F12: =SUMIFS(Transactions!$J$2:$J$399,Transactions!$Z$2:$Z$399,1) | G12: =ROUND(D12-F12,2) | H12: Keyword based: PPF/PF/EPF/provident fund.

Sheet Category Details
A1: Category Details
A3: Category | B3: Detail Sheet | C3: Rows | D3: Receipt Count | E3: Receipts | F3: Payment Count | G3: Payments | H3: Net
A4: Total | B4: Detail Total | C4: 398 | D4: 283 | E4: 17768567 | F4: 115 | G4: 18129258 | H4: -360691
A5: Cash | B5: Detail Cash | C5: 2 | D5: 1 | E5: 114500 | F5: 1 | G5: 24 | H5: 114476
A6: Recurring Transaction | B6: Detail Recurring Transaction | C6: 346 | D6: 250 | E6: 15926651 | F6: 96 | G6: 17904826 | H6: -1978174.6
A7: EMI | B7: Detail EMI | C7: 2 | D7: 2 | E7: 55541 | F7: 0 | G7: 0 | H7: 55541
A8: Salary | B8: Detail Salary | C8: 0 | D8: 0 | E8: 0 | F8: 0 | G8: 0 | H8: 0
A9: High Transaction | B9: Detail High Transaction | C9: 112 | D9: 59 | E9: 10963794 | F9: 53 | G9: 17146556 | H9: -6182762.4
A10: Total Receipts and Payments | B10: Detail Total Receipts and Payme | C10: 398 | D10: 283 | E10: 17768567 | F10: 115 | G10: 18129258 | H10: -360691
A11: UPI | B11: Detail UPI | C11: 36 | D11: 24 | E11: 416085 | F11: 12 | G11: 71816.63 | H11: 344268.37
A12: LIC | B12: Detail LIC | C12: 0 | D12: 0 | E12: 0 | F12: 0 | G12: 0 | H12: 0
A13: FD interest | B13: Detail FD interest | C13: 0 | D13: 0 | E13: 0 | F13: 0 | G13: 0 | H13: 0
A14: FD Deposit and withdrawals | B14: Detail FD Deposit and withdrawa | C14: 0 | D14: 0 | E14: 0 | F14: 0 | G14: 0 | H14: 0
A15: PPF/PF interest and contribution | B15: Detail PPF PF interest and cont | C15: 0 | D15: 0 | E15: 0 | F15: 0 | G15: 0 | H15: 0

Sheet Monthly Summary
A1: Month Key | B1: From | C1: To | D1: Period | E1: Transactions | F1: Opening Balance | G1: Dr Count | H1: Cr Count | I1: Payments | J1: Receipts | K1: Closing Balance | L1: Parsed Payments | M1: Parsed Receipts | N1: Payment Check | O1: Receipt Check
A2: 2026-04 | B2: 46113 | C2: 46143 | D2: Apr 2026 | E2: 398 | F2: 363191 | G2: 115 | H2: 283 | I2: 18129258 | J2: 17768567 | K2: 2500 | L2: =SUMIFS(Transactions!$J$2:$J$399,Transactions!$AA$2:$AA$399,">="&B2,Transactions!$AA$2:$AA$399,"<"&C2) | M2: =SUMIFS(Transactions!$K$2:$K$399,Transactions!$AA$2:$AA$399,">="&B2,Transactions!$AA$2:$AA$399,"<"&C2) | N2: =IF(ABS(I2-L2)<0.01,"OK","Check") | O2: =IF(ABS(J2-M2)<0.01,"OK","Check")

Sheet Transactions
A1: Seq | B1: Source File | C1: Statement From | D1: Statement To | E1: Date | F1: Value Date | G1: Narration | H1: Reference | I1: Direction | J1: Withdrawal | K1: Deposit | L1: Amount | M1: Closing Balance | N1: Categories | O1: Recurring? | P1: Recurring Key | Q1: Flag - Cash | R1: Flag - Recurring Transaction | S1: Flag - EMI | T1: Flag - Salary | U1: Flag - High Transaction | V1: Flag - UPI | W1: Flag - LIC | X1: Flag - FD interest | Y1: Flag - FD Deposit and withdrawals | Z1: Flag - PPF/PF interest and contribution | AA1: Month Date
A2: 1 | B2: 502 input.pdf | C2: 46113 | D2: 46142 | E2: 46114 | F2: 46114 | G2: DIGITA-MUMBAI/ IMPS/P2A/609147096215/HONEPELIMITEDPA/F09Hpcljige | I2: Receipt | J2: 0 | K2: 53200 | L2: 53200 | M2: 416391 | N2: Other | O2: No | P2: HONEPELIMITEDPA | Q2: 0 | R2: 0 | S2: 0 | T2: 0 | U2: 0 | V2: 0 | W2: 0 | X2: 0 | Y2: 0 | Z2: 0 | AA2: 46114
A3: 2 | B3: 502 input.pdf | C3: 46113 | D3: 46142 | E3: 46114 | F3: 46114 | G3: DIGITA-MUMBAI/ NEFT-YESAP60912594024-PhonePe Limited | I3: Receipt | J3: 0 | K3: 165179 | L3: 165179 | M3: 581570 | N3: High Transaction; Recurring Transaction | O3: Yes | P3: PHONEPE LIMITED | Q3: 0 | R3: 1 | S3: 0 | T3: 0 | U3: 1 | V3: 0 | W3: 0 | X3: 0 | Y3: 0 | Z3: 0 | AA3: 46114
A4: 3 | B4: 502 input.pdf | C4: 46113 | D4: 46142 | E4: 46114 | F4: 46114 | G4: UPI/6091426275 42627513 UPI/609142627513/04:54:21/UPI/dineshjogle086-5@ok | I4: Payment | J4: 2356 | K4: 0 | L4: 2356 | M4: 579214 | N4: UPI | O4: No | P4: DINESHJOGLE | Q4: 0 | R4: 0 | S4: 0 | T4: 0 | U4: 0 | V4: 1 | W4: 0 | X4: 0 | Y4: 0 | Z4: 0 | AA4: 46114
A5: 4 | B5: 502 input.pdf | C5: 46113 | D5: 46142 | E5: 46114 | F5: 46114 | G5: DIGITA-MUMBAI/ IMPS/P2A/609149979773/ONEMOBIKWIKSYST/IMPSAXB9100 | I5: Receipt | J5: 0 | K5: 35167.6 | L5: 35167.6 | M5: 614381.6 | N5: Other | O5: No | P5: ONEMOBIKWIKSYST | Q5: 0 | R5: 0 | S5: 0 | T5: 0 | U5: 0 | V5: 0 | W5: 0 | X5: 0 | Y5: 0 | Z5: 0 | AA5: 46114
A6: 5 | B6: 502 input.pdf | C6: 46113 | D6: 46142 | E6: 46114 | F6: 46114 | G6: UPI/6091243743 24374374 UPI/609124374374/11:47:28/UPI/prasadconstruction2 | I6: Receipt | J6: 0 | K6: 70000 | L6: 70000 | M6: 684381.6 | N6: UPI | O6: No | P6: PRASADCONSTRUCTION | Q6: 0 | R6: 0 | S6: 0 | T6: 0 | U6: 0 | V6: 1 | W6: 0 | X6: 0 | Y6: 0 | Z6: 0 | AA6: 46114
A7: 6 | B7: 502 input.pdf | C7: 46113 | D7: 46142 | E7: 46114 | F7: 46114 | G7: EBANK:WIB/1502 EBANK:WIB/1502021829/Edfs | I7: Payment | J7: 681881.6 | K7: 0 | L7: 681881.6 | M7: 2500 | N7: High Transaction; Recurring Transaction | O7: Yes | P7: EBANKWIB | Q7: 0 | R7: 1 | S7: 0 | T7: 0 | U7: 1 | V7: 0 | W7: 0 | X7: 0 | Y7: 0 | Z7: 0 | AA7: 46114
A8: 7 | B8: 502 input.pdf | C8: 46113 | D8: 46142 | E8: 46114 | F8: 46114 | G8: DIGITA-MUMBAI/ NEFT-FBPT260916108327-PREMIER CONVEYORS PRIVATE LI | I8: Receipt | J8: 0 | K8: 18409 | L8: 18409 | M8: 20909 | N8: EMI; Recurring Transaction | O8: Yes | P8: PREMIER CONVEYORS PRIVATE LI | Q8: 0 | R8: 1 | S8: 1 | T8: 0 | U8: 0 | V8: 0 | W8: 0 | X8: 0 | Y8: 0 | Z8: 0 | AA8: 46114
A9: 8 | B9: 502 input.pdf | C9: 46113 | D9: 46142 | E9: 46114 | F9: 46114 | G9: DIGITA-MUMBAI/ NEFT-CNRBH00121803213-QUALITY PLAST INDUSTRIES LIM | I9: Receipt | J9: 0 | K9: 121431 | L9: 121431 | M9: 142340 | N9: High Transaction; Recurring Transaction | O9: Yes | P9: QUALITY PLAST INDUSTRIES LIM | Q9: 0 | R9: 1 | S9: 0 | T9: 0 | U9: 1 | V9: 0 | W9: 0 | X9: 0 | Y9: 0 | Z9: 0 | AA9: 46114
A10: 9 | B10: 502 input.pdf | C10: 46113 | D10: 46142 | E10: 46114 | F10: 46114 | G10: UPI/6091779614 77961475 UPI/609177961475/16:34:33/UPI/q297956037@ybl/food | I10: Payment | J10: 1500 | K10: 0 | L10: 1500 | M10: 140840 | N10: UPI | O10: No | P10: UPI/# # UPI/#/#:#:#/UPI/Q#@YBL/FOOD | Q10: 0 | R10: 0 | S10: 0 | T10: 0 | U10: 0 | V10: 1 | W10: 0 | X10: 0 | Y10: 0 | Z10: 0 | AA10: 46114
A11: 10 | B11: 502 input.pdf | C11: 46113 | D11: 46142 | E11: 46114 | F11: 46114 | G11: DIGITA-MUMBAI/ IMPS/P2A/609116466512/AFZALSIRAJUDDIN/IMPSUOB9191 | I11: Receipt | J11: 0 | K11: 100000 | L11: 100000 | M11: 240840 | N11: High Transaction; Recurring Transaction | O11: Yes | P11: AFZALSIRAJUDDIN | Q11: 0 | R11: 1 | S11: 0 | T11: 0 | U11: 1 | V11: 0 | W11: 0 | X11: 0 | Y11: 0 | Z11: 0 | AA11: 46114
A12: 11 | B12: 502 input.pdf | C12: 46113 | D12: 46142 | E12: 46114 | F12: 46114 | G12: DIGITA-MUMBAI/ NEFT-KKBKH26091970510-VENKTESHWAR INDUSTRIAL CORPO | I12: Receipt | J12: 0 | K12: 10000 | L12: 10000 | M12: 250840 | N12: Recurring Transaction | O12: Yes | P12: VENKTESHWAR INDUSTRIAL CORPO | Q12: 0 | R12: 1 | S12: 0 | T12: 0 | U12: 0 | V12: 0 | W12: 0 | X12: 0 | Y12: 0 | Z12: 0 | AA12: 46114
A13: 12 | B13: 502 input.pdf | C13: 46113 | D13: 46142 | E13: 46114 | F13: 46114 | G13: EBANK:WIB/1502 ---------------------------------------------------------------------------------------------------------------------------------- Page Total: 9,34,077.60 5,73,386.60 2,500.00Cr ---------------------------------------------------------------------------------------------------------------------------------- Note: Cheques received in inward clearing will be considered for debiting/ returning on the basis opening balance in account Unless the constituent notifies the bank of any dis | I13: Payment | J13: 248340 | K13: 0 | L13: 248340 | M13: 2500 | N13: High Transaction; Recurring Transaction | O13: Yes | P13: EBANKWIB | Q13: 0 | R13: 1 | S13: 0 | T13: 0 | U13: 1 | V13: 0 | W13: 0 | X13: 0 | Y13: 0 | Z13: 0 | AA13: 46114
... A399: 398 | B399: 502 input.pdf | C399: 46113 | D399: 46142 | E399: 46142 | F399: 46142 | G399: EBANK:WIB/1506 EBANK:WIB/1506303993/Edfs ---------------------------------------------------------------------------------------------------------------------------------- Page Total: 4,73,075.05 2,64,697.00 2,500.00Cr ---------------------------------------------------------------------------------------------------------------------------------- Grand Total: 1,81,29,258.19 1,77,68,567.19 2,500.00Cr* ----------------------------------------------------------------------------------------------- | I399: Payment | J399: 128623.2 | K399: 0 | L399: 128623.2 | M399: 2500 | N399: High Transaction; Recurring Transaction | O399: Yes | P399: EBANKWIB | Q399: 0 | R399: 1 | S399: 0 | T399: 0 | U399: 1 | V399: 0 | W399: 0 | X399: 0 | Y399: 0 | Z399: 0 | AA399: 46142

Sheet Detail Total
A1: =HYPERLINK("#'Dashboard'!A1", "← Return to Dashboard") | B1: Total Transactions
A2: Rows | B2: 398 | C2: Match | D2: All transactions
A4: Seq | B4: Source File | C4: Statement From | D4: Statement To | E4: Date | F4: Value Date | G4: Narration | H4: Reference | I4: Direction | J4: Withdrawal | K4: Deposit | L4: Amount | M4: Closing Balance | N4: Categories | O4: Recurring? | P4: Recurring Key | Q4: Flag - Cash | R4: Flag - Recurring Transaction | S4: Flag - EMI | T4: Flag - Salary | U4: Flag - High Transaction | V4: Flag - UPI | W4: Flag - LIC | X4: Flag - FD interest | Y4: Flag - FD Deposit and withdrawals | Z4: Flag - PPF/PF interest and contribution | AA4: Month Date | AB4: View Source Row
A5: 1 | B5: 502 input.pdf | C5: 46113 | D5: 46142 | E5: 46114 | F5: 46114 | G5: DIGITA-MUMBAI/ IMPS/P2A/609147096215/HONEPELIMITEDPA/F09Hpcljige | I5: Receipt | J5: 0 | K5: 53200 | L5: 53200 | M5: 416391 | N5: Other | O5: No | P5: HONEPELIMITEDPA | Q5: 0 | R5: 0 | S5: 0 | T5: 0 | U5: 0 | V5: 0 | W5: 0 | X5: 0 | Y5: 0 | Z5: 0 | AA5: 46114 | AB5: =HYPERLINK("#'Transactions'!A2", "View Source Row")
A6: 2 | B6: 502 input.pdf | C6: 46113 | D6: 46142 | E6: 46114 | F6: 46114 | G6: DIGITA-MUMBAI/ NEFT-YESAP60912594024-PhonePe Limited | I6: Receipt | J6: 0 | K6: 165179 | L6: 165179 | M6: 581570 | N6: High Transaction; Recurring Transaction | O6: Yes | P6: PHONEPE LIMITED | Q6: 0 | R6: 1 | S6: 0 | T6: 0 | U6: 1 | V6: 0 | W6: 0 | X6: 0 | Y6: 0 | Z6: 0 | AA6: 46114 | AB6: =HYPERLINK("#'Transactions'!A3", "View Source Row")
A7: 3 | B7: 502 input.pdf | C7: 46113 | D7: 46142 | E7: 46114 | F7: 46114 | G7: UPI/6091426275 42627513 UPI/609142627513/04:54:21/UPI/dineshjogle086-5@ok | I7: Payment | J7: 2356 | K7: 0 | L7: 2356 | M7: 579214 | N7: UPI | O7: No | P7: DINESHJOGLE | Q7: 0 | R7: 0 | S7: 0 | T7: 0 | U7: 0 | V7: 1 | W7: 0 | X7: 0 | Y7: 0 | Z7: 0 | AA7: 46114 | AB7: =HYPERLINK("#'Transactions'!A4", "View Source Row")
A8: 4 | B8: 502 input.pdf | C8: 46113 | D8: 46142 | E8: 46114 | F8: 46114 | G8: DIGITA-MUMBAI/ IMPS/P2A/609149979773/ONEMOBIKWIKSYST/IMPSAXB9100 | I8: Receipt | J8: 0 | K8: 35167.6 | L8: 35167.6 | M8: 614381.6 | N8: Other | O8: No | P8: ONEMOBIKWIKSYST | Q8: 0 | R8: 0 | S8: 0 | T8: 0 | U8: 0 | V8: 0 | W8: 0 | X8: 0 | Y8: 0 | Z8: 0 | AA8: 46114 | AB8: =HYPERLINK("#'Transactions'!A5", "View Source Row")
A9: 5 | B9: 502 input.pdf | C9: 46113 | D9: 46142 | E9: 46114 | F9: 46114 | G9: UPI/6091243743 24374374 UPI/609124374374/11:47:28/UPI/prasadconstruction2 | I9: Receipt | J9: 0 | K9: 70000 | L9: 70000 | M9: 684381.6 | N9: UPI | O9: No | P9: PRASADCONSTRUCTION | Q9: 0 | R9: 0 | S9: 0 | T9: 0 | U9: 0 | V9: 1 | W9: 0 | X9: 0 | Y9: 0 | Z9: 0 | AA9: 46114 | AB9: =HYPERLINK("#'Transactions'!A6", "View Source Row")
A10: 6 | B10: 502 input.pdf | C10: 46113 | D10: 46142 | E10: 46114 | F10: 46114 | G10: EBANK:WIB/1502 EBANK:WIB/1502021829/Edfs | I10: Payment | J10: 681881.6 | K10: 0 | L10: 681881.6 | M10: 2500 | N10: High Transaction; Recurring Transaction | O10: Yes | P10: EBANKWIB | Q10: 0 | R10: 1 | S10: 0 | T10: 0 | U10: 1 | V10: 0 | W10: 0 | X10: 0 | Y10: 0 | Z10: 0 | AA10: 46114 | AB10: =HYPERLINK("#'Transactions'!A7", "View Source Row")
A11: 7 | B11: 502 input.pdf | C11: 46113 | D11: 46142 | E11: 46114 | F11: 46114 | G11: DIGITA-MUMBAI/ NEFT-FBPT260916108327-PREMIER CONVEYORS PRIVATE LI | I11: Receipt | J11: 0 | K11: 18409 | L11: 18409 | M11: 20909 | N11: EMI; Recurring Transaction | O11: Yes | P11: PREMIER CONVEYORS PRIVATE LI | Q11: 0 | R11: 1 | S11: 1 | T11: 0 | U11: 0 | V11: 0 | W11: 0 | X11: 0 | Y11: 0 | Z11: 0 | AA11: 46114 | AB11: =HYPERLINK("#'Transactions'!A8", "View Source Row")
A12: 8 | B12: 502 input.pdf | C12: 46113 | D12: 46142 | E12: 46114 | F12: 46114 | G12: DIGITA-MUMBAI/ NEFT-CNRBH00121803213-QUALITY PLAST INDUSTRIES LIM | I12: Receipt | J12: 0 | K12: 121431 | L12: 121431 | M12: 142340 | N12: High Transaction; Recurring Transaction | O12: Yes | P12: QUALITY PLAST INDUSTRIES LIM | Q12: 0 | R12: 1 | S12: 0 | T12: 0 | U12: 1 | V12: 0 | W12: 0 | X12: 0 | Y12: 0 | Z12: 0 | AA12: 46114 | AB12: =HYPERLINK("#'Transactions'!A9", "View Source Row")
A13: 9 | B13: 502 input.pdf | C13: 46113 | D13: 46142 | E13: 46114 | F13: 46114 | G13: UPI/6091779614 77961475 UPI/609177961475/16:34:33/UPI/q297956037@ybl/food | I13: Payment | J13: 1500 | K13: 0 | L13: 1500 | M13: 140840 | N13: UPI | O13: No | P13: UPI/# # UPI/#/#:#:#/UPI/Q#@YBL/FOOD | Q13: 0 | R13: 0 | S13: 0 | T13: 0 | U13: 0 | V13: 1 | W13: 0 | X13: 0 | Y13: 0 | Z13: 0 | AA13: 46114 | AB13: =HYPERLINK("#'Transactions'!A10", "View Source Row")
A14: 10 | B14: 502 input.pdf | C14: 46113 | D14: 46142 | E14: 46114 | F14: 46114 | G14: DIGITA-MUMBAI/ IMPS/P2A/609116466512/AFZALSIRAJUDDIN/IMPSUOB9191 | I14: Receipt | J14: 0 | K14: 100000 | L14: 100000 | M14: 240840 | N14: High Transaction; Recurring Transaction | O14: Yes | P14: AFZALSIRAJUDDIN | Q14: 0 | R14: 1 | S14: 0 | T14: 0 | U14: 1 | V14: 0 | W14: 0 | X14: 0 | Y14: 0 | Z14: 0 | AA14: 46114 | AB14: =HYPERLINK("#'Transactions'!A11", "View Source Row")
A15: 11 | B15: 502 input.pdf | C15: 46113 | D15: 46142 | E15: 46114 | F15: 46114 | G15: DIGITA-MUMBAI/ NEFT-KKBKH26091970510-VENKTESHWAR INDUSTRIAL CORPO | I15: Receipt | J15: 0 | K15: 10000 | L15: 10000 | M15: 250840 | N15: Recurring Transaction | O15: Yes | P15: VENKTESHWAR INDUSTRIAL CORPO | Q15: 0 | R15: 1 | S15: 0 | T15: 0 | U15: 0 | V15: 0 | W15: 0 | X15: 0 | Y15: 0 | Z15: 0 | AA15: 46114 | AB15: =HYPERLINK("#'Transactions'!A12", "View Source Row")
A16: 12 | B16: 502 input.pdf | C16: 46113 | D16: 46142 | E16: 46114 | F16: 46114 | G16: EBANK:WIB/1502 ---------------------------------------------------------------------------------------------------------------------------------- Page Total: 9,34,077.60 5,73,386.60 2,500.00Cr ---------------------------------------------------------------------------------------------------------------------------------- Note: Cheques received in inward clearing will be considered for debiting/ returning on the basis opening balance in account Unless the constituent notifies the bank of any dis | I16: Payment | J16: 248340 | K16: 0 | L16: 248340 | M16: 2500 | N16: High Transaction; Recurring Transaction | O16: Yes | P16: EBANKWIB | Q16: 0 | R16: 1 | S16: 0 | T16: 0 | U16: 1 | V16: 0 | W16: 0 | X16: 0 | Y16: 0 | Z16: 0 | AA16: 46114 | AB16: =HYPERLINK("#'Transactions'!A13", "View Source Row")
A17: 13 | B17: 502 input.pdf | C17: 46113 | D17: 46142 | E17: 46114 | F17: 46114 | G17: DIGITA-MUMBAI/ NEFT-YESAP60924833309-PhonePe Limited | I17: Receipt | J17: 0 | K17: 188588.4 | L17: 188588.4 | M17: 191088.4 | N17: High Transaction; Recurring Transaction | O17: Yes | P17: PHONEPE LIMITED | Q17: 0 | R17: 1 | S17: 0 | T17: 0 | U17: 1 | V17: 0 | W17: 0 | X17: 0 | Y17: 0 | Z17: 0 | AA17: 46114 | AB17: =HYPERLINK("#'Transactions'!A14", "View Source Row")
A18: 14 | B18: 502 input.pdf | C18: 46113 | D18: 46142 | E18: 46114 | F18: 46114 | G18: DIGITA-MUMBAI/ NEFT-AXNPN09202196281-PHONEPE LIMITED-PAYMENT AGGR | I18: Receipt | J18: 0 | K18: 50884.1 | L18: 50884.1 | M18: 241972.5 | N18: Recurring Transaction | O18: Yes | P18: PHONEPE LIMITED | Q18: 0 | R18: 1 | S18: 0 | T18: 0 | U18: 0 | V18: 0 | W18: 0 | X18: 0 | Y18: 0 | Z18: 0 | AA18: 46114 | AB18: =HYPERLINK("#'Transactions'!A15", "View Source Row")
A19: 15 | B19: 502 input.pdf | C19: 46113 | D19: 46142 | E19: 46114 | F19: 46114 | G19: DIGITA-MUMBAI/ NEFT-AXISCN1298773772-ONE MOBIKWIK SYSTEMS LIMITED https://cbdrpt101.bankofbaroda.co.in:22000/finbranch/arjspmorph/INFENG/tran_rpt.jsp?... 04-05-2026 | I19: Receipt | J19: 0 | K19: 26312 | L19: 26312 | M19: 268284.5 | N19: Recurring Transaction | O19: Yes | P19: ONE MOBIKWIK SYSTEMS LIMITED HTTPS | Q19: 0 | R19: 1 | S19: 0 | T19: 0 | U19: 0 | V19: 0 | W19: 0 | X19: 0 | Y19: 0 | Z19: 0 | AA19: 46114 | AB19: =HYPERLINK("#'Transactions'!A16", "View Source Row")
A20: 16 | B20: 502 input.pdf | C20: 46113 | D20: 46142 | E20: 46114 | F20: 46114 | G20: DIGITA-MUMBAI/ IMPS/P2A/609208556385/OMSANITRANSPORT/IMPSUOB9195 | I20: Receipt | J20: 0 | K20: 16450 | L20: 16450 | M20: 284734.5 | N20: Recurring Transaction | O20: Yes | P20: OMSANITRANSPORT | Q20: 0 | R20: 1 | S20: 0 | T20: 0 | U20: 0 | V20: 0 | W20: 0 | X20: 0 | Y20: 0 | Z20: 0 | AA20: 46114 | AB20: =HYPERLINK("#'Transactions'!A17", "View Source Row")
A21: 17 | B21: 502 input.pdf | C21: 46113 | D21: 46142 | E21: 46114 | F21: 46114 | G21: DIGITA-MUMBAI/ NEFT-AXISCN1298906804-PINE LABS PRIVATE LIMITED-NO | I21: Receipt | J21: 0 | K21: 61903 | L21: 61903 | M21: 346637.5 | N21: Recurring Transaction | O21: Yes | P21: PINE LABS PRIVATE LIMITED | Q21: 0 | R21: 1 | S21: 0 | T21: 0 | U21: 0 | V21: 0 | W21: 0 | X21: 0 | Y21: 0 | Z21: 0 | AA21: 46114 | AB21: =HYPERLINK("#'Transactions'!A18", "View Source Row")
A22: 18 | B22: 502 input.pdf | C22: 46113 | D22: 46142 | E22: 46114 | F22: 46114 | G22: DIGITA-MUMBAI/ NEFT-AXISCN1299028324-PINE LABS PRIVATE LIMITED-NO | I22: Receipt | J22: 0 | K22: 166884 | L22: 166884 | M22: 513521.5 | N22: High Transaction; Recurring Transaction | O22: Yes | P22: PINE LABS PRIVATE LIMITED | Q22: 0 | R22: 1 | S22: 0 | T22: 0 | U22: 1 | V22: 0 | W22: 0 | X22: 0 | Y22: 0 | Z22: 0 | AA22: 46114 | AB22: =HYPERLINK("#'Transactions'!A19", "View Source Row")
A23: 19 | B23: 502 input.pdf | C23: 46113 | D23: 46142 | E23: 46114 | F23: 46114 | G23: UPI/6092378308 37830859 UPI/609237830859/11:20:36/UPI/9850754712-3@ybl/st | I23: Payment | J23: 4000 | K23: 0 | L23: 4000 | M23: 509521.5 | N23: UPI | O23: No | P23: UPI/# # UPI/#/#:#:#/UPI/#-#@YBL/ST | Q23: 0 | R23: 0 | S23: 0 | T23: 0 | U23: 0 | V23: 1 | W23: 0 | X23: 0 | Y23: 0 | Z23: 0 | AA23: 46114 | AB23: =HYPERLINK("#'Transactions'!A20", "View Source Row")
A24: 20 | B24: 502 input.pdf | C24: 46113 | D24: 46142 | E24: 46114 | F24: 46114 | G24: DIGITA-MUMBAI/ IMPS/P2A/609211135154/SHREE GANESH EN/dieselVVS91 | I24: Receipt | J24: 0 | K24: 63308 | L24: 63308 | M24: 572829.5 | N24: Recurring Transaction | O24: Yes | P24: SHREE GANESH EN | Q24: 0 | R24: 1 | S24: 0 | T24: 0 | U24: 0 | V24: 0 | W24: 0 | X24: 0 | Y24: 0 | Z24: 0 | AA24: 46114 | AB24: =HYPERLINK("#'Transactions'!A21", "View Source Row")
A25: 21 | B25: 502 input.pdf | C25: 46113 | D25: 46142 | E25: 46114 | F25: 46114 | G25: DIGITA-MUMBAI/ NEFT-KKBKH26092777992-VENKTESHWAR INDUSTRIAL CORPO | I25: Receipt | J25: 0 | K25: 18088 | L25: 18088 | M25: 590917.5 | N25: Recurring Transaction | O25: Yes | P25: VENKTESHWAR INDUSTRIAL CORPO | Q25: 0 | R25: 1 | S25: 0 | T25: 0 | U25: 0 | V25: 0 | W25: 0 | X25: 0 | Y25: 0 | Z25: 0 | AA25: 46114 | AB25: =HYPERLINK("#'Transactions'!A22", "View Source Row")
A26: 22 | B26: 502 input.pdf | C26: 46113 | D26: 46142 | E26: 46114 | F26: 46114 | G26: UPI/6092013389 1338963 UPI/609201338963/12:38:06/UPI/gpay-11193876450@ok | I26: Payment | J26: 2800 | K26: 0 | L26: 2800 | M26: 588117.5 | N26: UPI | O26: No | P26: UPI/# # UPI/#/#:#:#/UPI/GPAY-#@OK | Q26: 0 | R26: 0 | S26: 0 | T26: 0 | U26: 0 | V26: 1 | W26: 0 | X26: 0 | Y26: 0 | Z26: 0 | AA26: 46114 | AB26: =HYPERLINK("#'Transactions'!A23", "View Source Row")
A27: 23 | B27: 502 input.pdf | C27: 46113 | D27: 46142 | E27: 46114 | F27: 46114 | G27: DIGITA-MUMBAI/ NEFT-NKGSH26092846591-GEBI PRODUCTS PRIVATE LIMITE | I27: Receipt | J27: 0 | K27: 12813 | L27: 12813 | M27: 600930.5 | N27: Recurring Transaction | O27: Yes | P27: GEBI PRODUCTS PRIVATE LIMITE | Q27: 0 | R27: 1 | S27: 0 | T27: 0 | U27: 0 | V27: 0 | W27: 0 | X27: 0 | Y27: 0 | Z27: 0 | AA27: 46114 | AB27: =HYPERLINK("#'Transactions'!A24", "View Source Row")
A28: 24 | B28: 502 input.pdf | C28: 46113 | D28: 46142 | E28: 46114 | F28: 46114 | G28: DIGITA-MUMBAI/ NEFT-IDIBH09236262399-JAI AMBE TRANSPORT | I28: Receipt | J28: 0 | K28: 4378 | L28: 4378 | M28: 605308.5 | N28: Recurring Transaction | O28: Yes | P28: JAI AMBE TRANSPORT | Q28: 0 | R28: 1 | S28: 0 | T28: 0 | U28: 0 | V28: 0 | W28: 0 | X28: 0 | Y28: 0 | Z28: 0 | AA28: 46114 | AB28: =HYPERLINK("#'Transactions'!A25", "View Source Row")
A29: 25 | B29: 502 input.pdf | C29: 46113 | D29: 46142 | E29: 46114 | F29: 46114 | G29: DIGITA-MUMBAI/ NEFT-HDFCH00905140576-Adekar enterprises pvt ltd | I29: Receipt | J29: 0 | K29: 138674 | L29: 138674 | M29: 743982.5 | N29: High Transaction; Recurring Transaction | O29: Yes | P29: ADEKAR ENTERPRISES PVT LTD | Q29: 0 | R29: 1 | S29: 0 | T29: 0 | U29: 1 | V29: 0 | W29: 0 | X29: 0 | Y29: 0 | Z29: 0 | AA29: 46114 | AB29: =HYPERLINK("#'Transactions'!A26", "View Source Row")
A30: 26 | B30: 502 input.pdf | C30: 46113 | D30: 46142 | E30: 46114 | F30: 46114 | G30: DIGITA-MUMBAI/ NEFT-TDCBH26092001785-V C ENTERPRISES | I30: Receipt | J30: 0 | K30: 50000 | L30: 50000 | M30: 793982.5 | N30: Recurring Transaction | O30: Yes | P30: V C ENTERPRISES | Q30: 0 | R30: 1 | S30: 0 | T30: 0 | U30: 0 | V30: 0 | W30: 0 | X30: 0 | Y30: 0 | Z30: 0 | AA30: 46114 | AB30: =HYPERLINK("#'Transactions'!A27", "View Source Row")
A31: 27 | B31: 502 input.pdf | C31: 46113 | D31: 46142 | E31: 46114 | F31: 46114 | G31: EBANK:WIB/1502 EBANK:WIB/1502234210/Edfs | I31: Payment | J31: 791482.5 | K31: 0 | L31: 791482.5 | M31: 2500 | N31: High Transaction; Recurring Transaction | O31: Yes | P31: EBANKWIB | Q31: 0 | R31: 1 | S31: 0 | T31: 0 | U31: 1 | V31: 0 | W31: 0 | X31: 0 | Y31: 0 | Z31: 0 | AA31: 46114 | AB31: =HYPERLINK("#'Transactions'!A28", "View Source Row")
A32: 28 | B32: 502 input.pdf | C32: 46113 | D32: 46142 | E32: 46114 | F32: 46114 | G32: DIGITA-MUMBAI/ ---------------------------------------------------------------------------------------------------------------------------------- Page Total: 7,98,282.50 8,34,458.50 38,676.00Cr ---------------------------------------------------------------------------------------------------------------------------------- Note: Cheques received in inward clearing will be considered for debiting/ returning on the basis opening balance in account Unless the constituent notifies the bank of any di | I32: Receipt | J32: 0 | K32: 36176 | L32: 36176 | M32: 38676 | N32: Recurring Transaction | O32: Yes | P32: PAGE TOTAL CR | Q32: 0 | R32: 1 | S32: 0 | T32: 0 | U32: 0 | V32: 0 | W32: 0 | X32: 0 | Y32: 0 | Z32: 0 | AA32: 46114 | AB32: =HYPERLINK("#'Transactions'!A29", "View Source Row")
A33: 29 | B33: 502 input.pdf | C33: 46113 | D33: 46142 | E33: 46114 | F33: 46114 | G33: DIGITA-MUMBAI/ NEFT-KKBKH26092921670-ATLAS COMMODITIES PRIVATE LI | I33: Receipt | J33: 0 | K33: 4353 | L33: 4353 | M33: 43029 | N33: Recurring Transaction | O33: Yes | P33: ATLAS COMMODITIES PRIVATE LI | Q33: 0 | R33: 1 | S33: 0 | T33: 0 | U33: 0 | V33: 0 | W33: 0 | X33: 0 | Y33: 0 | Z33: 0 | AA33: 46114 | AB33: =HYPERLINK("#'Transactions'!A30", "View Source Row")
A34: 30 | B34: 502 input.pdf | C34: 46113 | D34: 46142 | E34: 46115 | F34: 46115 | G34: DIGITA-MUMBAI/ NEFT-YESAP60934071902-PhonePe Limited | I34: Receipt | J34: 0 | K34: 173393.9 | L34: 173393.9 | M34: 216422.9 | N34: High Transaction; Recurring Transaction | O34: Yes | P34: PHONEPE LIMITED | Q34: 0 | R34: 1 | S34: 0 | T34: 0 | U34: 1 | V34: 0 | W34: 0 | X34: 0 | Y34: 0 | Z34: 0 | AA34: 46115 | AB34: =HYPERLINK("#'Transactions'!A31", "View Source Row")
A35: 31 | B35: 502 input.pdf | C35: 46113 | D35: 46142 | E35: 46115 | F35: 46115 | G35: DIGITA-MUMBAI/ NEFT-AXNPN09311160907-PHONEPE LIMITED-PAYMENT AGGR | I35: Receipt | J35: 0 | K35: 53957.68 | L35: 53957.68 | M35: 270380.58 | N35: Recurring Transaction | O35: Yes | P35: PHONEPE LIMITED | Q35: 0 | R35: 1 | S35: 0 | T35: 0 | U35: 0 | V35: 0 | W35: 0 | X35: 0 | Y35: 0 | Z35: 0 | AA35: 46115 | AB35: =HYPERLINK("#'Transactions'!A32", "View Source Row")
A36: 32 | B36: 502 input.pdf | C36: 46113 | D36: 46142 | E36: 46115 | F36: 46115 | G36: DIGITA-MUMBAI/ NEFT-AXISCN1300289999-ONE MOBIKWIK SYSTEMS LIMITED | I36: Receipt | J36: 0 | K36: 21700 | L36: 21700 | M36: 292080.58 | N36: Recurring Transaction | O36: Yes | P36: ONE MOBIKWIK SYSTEMS LIMITED | Q36: 0 | R36: 1 | S36: 0 | T36: 0 | U36: 0 | V36: 0 | W36: 0 | X36: 0 | Y36: 0 | Z36: 0 | AA36: 46115 | AB36: =HYPERLINK("#'Transactions'!A33", "View Source Row")
A37: 33 | B37: 502 input.pdf | C37: 46113 | D37: 46142 | E37: 46115 | F37: 46115 | G37: DIGITA-MUMBAI/ IMPS/P2A/609308206742/S TRANS 14851/Mh04ju3738I | I37: Receipt | J37: 0 | K37: 5750 | L37: 5750 | M37: 297830.58 | N37: Recurring Transaction | O37: Yes | P37: DIGITA-MUMBAI/ IMPS/P#A/#/S TRANS #/MH#JU#I | Q37: 0 | R37: 1 | S37: 0 | T37: 0 | U37: 0 | V37: 0 | W37: 0 | X37: 0 | Y37: 0 | Z37: 0 | AA37: 46115 | AB37: =HYPERLINK("#'Transactions'!A34", "View Source Row")
A38: 34 | B38: 502 input.pdf | C38: 46113 | D38: 46142 | E38: 46115 | F38: 46115 | G38: DIGITA-MUMBAI/ NEFT-AXISCN1300388689-PINE LABS PRIVATE LIMITED-NO | I38: Receipt | J38: 0 | K38: 112894 | L38: 112894 | M38: 410724.58 | N38: High Transaction; Recurring Transaction | O38: Yes | P38: PINE LABS PRIVATE LIMITED | Q38: 0 | R38: 1 | S38: 0 | T38: 0 | U38: 1 | V38: 0 | W38: 0 | X38: 0 | Y38: 0 | Z38: 0 | AA38: 46115 | AB38: =HYPERLINK("#'Transactions'!A35", "View Source Row")
A39: 35 | B39: 502 input.pdf | C39: 46113 | D39: 46142 | E39: 46115 | F39: 46115 | G39: DIGITA-MUMBAI/ IMPS/P2A/609312855509/AFZALSIRAJUDDIN/IMPSUOB9191 | I39: Receipt | J39: 0 | K39: 200000 | L39: 200000 | M39: 610724.58 | N39: High Transaction; Recurring Transaction | O39: Yes | P39: AFZALSIRAJUDDIN | Q39: 0 | R39: 1 | S39: 0 | T39: 0 | U39: 1 | V39: 0 | W39: 0 | X39: 0 | Y39: 0 | Z39: 0 | AA39: 46115 | AB39: =HYPERLINK("#'Transactions'!A36", "View Source Row")
A40: 36 | B40: 502 input.pdf | C40: 46113 | D40: 46142 | E40: 46115 | F40: 46115 | G40: DIGITA-MUMBAI/ NEFT-002663976089-GANGAMAI INDUSTRIES AND CONSTR | I40: Receipt | J40: 0 | K40: 180880 | L40: 180880 | M40: 791604.58 | N40: High Transaction | O40: No | P40: GANGAMAI INDUSTRIES AND CONSTR | Q40: 0 | R40: 0 | S40: 0 | T40: 0 | U40: 1 | V40: 0 | W40: 0 | X40: 0 | Y40: 0 | Z40: 0 | AA40: 46115 | AB40: =HYPERLINK("#'Transactions'!A37", "View Source Row")
A41: 37 | B41: 502 input.pdf | C41: 46113 | D41: 46142 | E41: 46115 | F41: 46115 | G41: EBANK:WIB/1502 EBANK:WIB/1502413595/Edfs | I41: Payment | J41: 790104.58 | K41: 0 | L41: 790104.58 | M41: 1500 | N41: High Transaction; Recurring Transaction | O41: Yes | P41: EBANKWIB | Q41: 0 | R41: 1 | S41: 0 | T41: 0 | U41: 1 | V41: 0 | W41: 0 | X41: 0 | Y41: 0 | Z41: 0 | AA41: 46115 | AB41: =HYPERLINK("#'Transactions'!A38", "View Source Row")
...

Sheet Detail Cash
A1: =HYPERLINK("#'Dashboard'!A1", "← Return to Dashboard") | B1: Cash Transactions
A2: Rows | B2: 2 | C2: Match | D2: Cash
A4: Seq | B4: Source File | C4: Statement From | D4: Statement To | E4: Date | F4: Value Date | G4: Narration | H4: Reference | I4: Direction | J4: Withdrawal | K4: Deposit | L4: Amount | M4: Closing Balance | N4: Categories | O4: Recurring? | P4: Recurring Key | Q4: Flag - Cash | R4: Flag - Recurring Transaction | S4: Flag - EMI | T4: Flag - Salary | U4: Flag - High Transaction | V4: Flag - UPI | W4: Flag - LIC | X4: Flag - FD interest | Y4: Flag - FD Deposit and withdrawals | Z4: Flag - PPF/PF interest and contribution | AA4: Month Date | AB4: View Source Row
A5: 75 | B5: 502 input.pdf | C5: 46113 | D5: 46142 | E5: 46119 | F5: 46119 | G5: BY CASH ---------------------------------------------------------------------------------------------------------------------------------- Page Total: 5,32,609.72 5,77,390.07 1,76,796.35Cr ---------------------------------------------------------------------------------------------------------------------------------- Note: Cheques received in inward clearing will be considered for debiting/ returning on the basis opening balance in account Unless the constituent notifies the bank of any discrep | I5: Receipt | J5: 0 | K5: 114500 | L5: 114500 | M5: 176796.35 | N5: Cash; High Transaction; Recurring Transaction | O5: Yes | P5: PAGE TOTAL CR | Q5: 1 | R5: 1 | S5: 0 | T5: 0 | U5: 1 | V5: 0 | W5: 0 | X5: 0 | Y5: 0 | Z5: 0 | AA5: 46119 | AB5: =HYPERLINK("#'Transactions'!A76", "View Source Row")
A6: 86 | B6: 502 input.pdf | C6: 46113 | D6: 46142 | E6: 46120 | F6: 46120 | G6: Chg Cash Chg Cash handling for:30-03-2026 | I6: Payment | J6: 24 | K6: 0 | L6: 24 | M6: 294225 | N6: Cash | O6: No | P6: CHG CASH CHG CASH HANDLING FOR | Q6: 1 | R6: 0 | S6: 0 | T6: 0 | U6: 0 | V6: 0 | W6: 0 | X6: 0 | Y6: 0 | Z6: 0 | AA6: 46120 | AB6: =HYPERLINK("#'Transactions'!A87", "View Source Row")

Sheet Detail Recurring Transaction
A1: =HYPERLINK("#'Dashboard'!A1", "← Return to Dashboard") | B1: Recurring Transaction Transactions
A2: Rows | B2: 346 | C2: Match | D2: Recurring Transaction
A4: Seq | B4: Source File | C4: Statement From | D4: Statement To | E4: Date | F4: Value Date | G4: Narration | H4: Reference | I4: Direction | J4: Withdrawal | K4: Deposit | L4: Amount | M4: Closing Balance | N4: Categories | O4: Recurring? | P4: Recurring Key | Q4: Flag - Cash | R4: Flag - Recurring Transaction | S4: Flag - EMI | T4: Flag - Salary | U4: Flag - High Transaction | V4: Flag - UPI | W4: Flag - LIC | X4: Flag - FD interest | Y4: Flag - FD Deposit and withdrawals | Z4: Flag - PPF/PF interest and contribution | AA4: Month Date | AB4: View Source Row
A5: 2 | B5: 502 input.pdf | C5: 46113 | D5: 46142 | E5: 46114 | F5: 46114 | G5: DIGITA-MUMBAI/ NEFT-YESAP60912594024-PhonePe Limited | I5: Receipt | J5: 0 | K5: 165179 | L5: 165179 | M5: 581570 | N5: High Transaction; Recurring Transaction | O5: Yes | P5: PHONEPE LIMITED | Q5: 0 | R5: 1 | S5: 0 | T5: 0 | U5: 1 | V5: 0 | W5: 0 | X5: 0 | Y5: 0 | Z5: 0 | AA5: 46114 | AB5: =HYPERLINK("#'Transactions'!A3", "View Source Row")
A6: 6 | B6: 502 input.pdf | C6: 46113 | D6: 46142 | E6: 46114 | F6: 46114 | G6: EBANK:WIB/1502 EBANK:WIB/1502021829/Edfs | I6: Payment | J6: 681881.6 | K6: 0 | L6: 681881.6 | M6: 2500 | N6: High Transaction; Recurring Transaction | O6: Yes | P6: EBANKWIB | Q6: 0 | R6: 1 | S6: 0 | T6: 0 | U6: 1 | V6: 0 | W6: 0 | X6: 0 | Y6: 0 | Z6: 0 | AA6: 46114 | AB6: =HYPERLINK("#'Transactions'!A7", "View Source Row")
A7: 7 | B7: 502 input.pdf | C7: 46113 | D7: 46142 | E7: 46114 | F7: 46114 | G7: DIGITA-MUMBAI/ NEFT-FBPT260916108327-PREMIER CONVEYORS PRIVATE LI | I7: Receipt | J7: 0 | K7: 18409 | L7: 18409 | M7: 20909 | N7: EMI; Recurring Transaction | O7: Yes | P7: PREMIER CONVEYORS PRIVATE LI | Q7: 0 | R7: 1 | S7: 1 | T7: 0 | U7: 0 | V7: 0 | W7: 0 | X7: 0 | Y7: 0 | Z7: 0 | AA7: 46114 | AB7: =HYPERLINK("#'Transactions'!A8", "View Source Row")
A8: 8 | B8: 502 input.pdf | C8: 46113 | D8: 46142 | E8: 46114 | F8: 46114 | G8: DIGITA-MUMBAI/ NEFT-CNRBH00121803213-QUALITY PLAST INDUSTRIES LIM | I8: Receipt | J8: 0 | K8: 121431 | L8: 121431 | M8: 142340 | N8: High Transaction; Recurring Transaction | O8: Yes | P8: QUALITY PLAST INDUSTRIES LIM | Q8: 0 | R8: 1 | S8: 0 | T8: 0 | U8: 1 | V8: 0 | W8: 0 | X8: 0 | Y8: 0 | Z8: 0 | AA8: 46114 | AB8: =HYPERLINK("#'Transactions'!A9", "View Source Row")
A9: 10 | B9: 502 input.pdf | C9: 46113 | D9: 46142 | E9: 46114 | F9: 46114 | G9: DIGITA-MUMBAI/ IMPS/P2A/609116466512/AFZALSIRAJUDDIN/IMPSUOB9191 | I9: Receipt | J9: 0 | K9: 100000 | L9: 100000 | M9: 240840 | N9: High Transaction; Recurring Transaction | O9: Yes | P9: AFZALSIRAJUDDIN | Q9: 0 | R9: 1 | S9: 0 | T9: 0 | U9: 1 | V9: 0 | W9: 0 | X9: 0 | Y9: 0 | Z9: 0 | AA9: 46114 | AB9: =HYPERLINK("#'Transactions'!A11", "View Source Row")
A10: 11 | B10: 502 input.pdf | C10: 46113 | D10: 46142 | E10: 46114 | F10: 46114 | G10: DIGITA-MUMBAI/ NEFT-KKBKH26091970510-VENKTESHWAR INDUSTRIAL CORPO | I10: Receipt | J10: 0 | K10: 10000 | L10: 10000 | M10: 250840 | N10: Recurring Transaction | O10: Yes | P10: VENKTESHWAR INDUSTRIAL CORPO | Q10: 0 | R10: 1 | S10: 0 | T10: 0 | U10: 0 | V10: 0 | W10: 0 | X10: 0 | Y10: 0 | Z10: 0 | AA10: 46114 | AB10: =HYPERLINK("#'Transactions'!A12", "View Source Row")
A11: 12 | B11: 502 input.pdf | C11: 46113 | D11: 46142 | E11: 46114 | F11: 46114 | G11: EBANK:WIB/1502 ---------------------------------------------------------------------------------------------------------------------------------- Page Total: 9,34,077.60 5,73,386.60 2,500.00Cr ---------------------------------------------------------------------------------------------------------------------------------- Note: Cheques received in inward clearing will be considered for debiting/ returning on the basis opening balance in account Unless the constituent notifies the bank of any dis | I11: Payment | J11: 248340 | K11: 0 | L11: 248340 | M11: 2500 | N11: High Transaction; Recurring Transaction | O11: Yes | P11: EBANKWIB | Q11: 0 | R11: 1 | S11: 0 | T11: 0 | U11: 1 | V11: 0 | W11: 0 | X11: 0 | Y11: 0 | Z11: 0 | AA11: 46114 | AB11: =HYPERLINK("#'Transactions'!A13", "View Source Row")
A12: 13 | B12: 502 input.pdf | C12: 46113 | D12: 46142 | E12: 46114 | F12: 46114 | G12: DIGITA-MUMBAI/ NEFT-YESAP60924833309-PhonePe Limited | I12: Receipt | J12: 0 | K12: 188588.4 | L12: 188588.4 | M12: 191088.4 | N12: High Transaction; Recurring Transaction | O12: Yes | P12: PHONEPE LIMITED | Q12: 0 | R12: 1 | S12: 0 | T12: 0 | U12: 1 | V12: 0 | W12: 0 | X12: 0 | Y12: 0 | Z12: 0 | AA12: 46114 | AB12: =HYPERLINK("#'Transactions'!A14", "View Source Row")
A13: 14 | B13: 502 input.pdf | C13: 46113 | D13: 46142 | E13: 46114 | F13: 46114 | G13: DIGITA-MUMBAI/ NEFT-AXNPN09202196281-PHONEPE LIMITED-PAYMENT AGGR | I13: Receipt | J13: 0 | K13: 50884.1 | L13: 50884.1 | M13: 241972.5 | N13: Recurring Transaction | O13: Yes | P13: PHONEPE LIMITED | Q13: 0 | R13: 1 | S13: 0 | T13: 0 | U13: 0 | V13: 0 | W13: 0 | X13: 0 | Y13: 0 | Z13: 0 | AA13: 46114 | AB13: =HYPERLINK("#'Transactions'!A15", "View Source Row")
A14: 15 | B14: 502 input.pdf | C14: 46113 | D14: 46142 | E14: 46114 | F14: 46114 | G14: DIGITA-MUMBAI/ NEFT-AXISCN1298773772-ONE MOBIKWIK SYSTEMS LIMITED https://cbdrpt101.bankofbaroda.co.in:22000/finbranch/arjspmorph/INFENG/tran_rpt.jsp?... 04-05-2026 | I14: Receipt | J14: 0 | K14: 26312 | L14: 26312 | M14: 268284.5 | N14: Recurring Transaction | O14: Yes | P14: ONE MOBIKWIK SYSTEMS LIMITED HTTPS | Q14: 0 | R14: 1 | S14: 0 | T14: 0 | U14: 0 | V14: 0 | W14: 0 | X14: 0 | Y14: 0 | Z14: 0 | AA14: 46114 | AB14: =HYPERLINK("#'Transactions'!A16", "View Source Row")
A15: 16 | B15: 502 input.pdf | C15: 46113 | D15: 46142 | E15: 46114 | F15: 46114 | G15: DIGITA-MUMBAI/ IMPS/P2A/609208556385/OMSANITRANSPORT/IMPSUOB9195 | I15: Receipt | J15: 0 | K15: 16450 | L15: 16450 | M15: 284734.5 | N15: Recurring Transaction | O15: Yes | P15: OMSANITRANSPORT | Q15: 0 | R15: 1 | S15: 0 | T15: 0 | U15: 0 | V15: 0 | W15: 0 | X15: 0 | Y15: 0 | Z15: 0 | AA15: 46114 | AB15: =HYPERLINK("#'Transactions'!A17", "View Source Row")
A16: 17 | B16: 502 input.pdf | C16: 46113 | D16: 46142 | E16: 46114 | F16: 46114 | G16: DIGITA-MUMBAI/ NEFT-AXISCN1298906804-PINE LABS PRIVATE LIMITED-NO | I16: Receipt | J16: 0 | K16: 61903 | L16: 61903 | M16: 346637.5 | N16: Recurring Transaction | O16: Yes | P16: PINE LABS PRIVATE LIMITED | Q16: 0 | R16: 1 | S16: 0 | T16: 0 | U16: 0 | V16: 0 | W16: 0 | X16: 0 | Y16: 0 | Z16: 0 | AA16: 46114 | AB16: =HYPERLINK("#'Transactions'!A18", "View Source Row")
A17: 18 | B17: 502 input.pdf | C17: 46113 | D17: 46142 | E17: 46114 | F17: 46114 | G17: DIGITA-MUMBAI/ NEFT-AXISCN1299028324-PINE LABS PRIVATE LIMITED-NO | I17: Receipt | J17: 0 | K17: 166884 | L17: 166884 | M17: 513521.5 | N17: High Transaction; Recurring Transaction | O17: Yes | P17: PINE LABS PRIVATE LIMITED | Q17: 0 | R17: 1 | S17: 0 | T17: 0 | U17: 1 | V17: 0 | W17: 0 | X17: 0 | Y17: 0 | Z17: 0 | AA17: 46114 | AB17: =HYPERLINK("#'Transactions'!A19", "View Source Row")
A18: 20 | B18: 502 input.pdf | C18: 46113 | D18: 46142 | E18: 46114 | F18: 46114 | G18: DIGITA-MUMBAI/ IMPS/P2A/609211135154/SHREE GANESH EN/dieselVVS91 | I18: Receipt | J18: 0 | K18: 63308 | L18: 63308 | M18: 572829.5 | N18: Recurring Transaction | O18: Yes | P18: SHREE GANESH EN | Q18: 0 | R18: 1 | S18: 0 | T18: 0 | U18: 0 | V18: 0 | W18: 0 | X18: 0 | Y18: 0 | Z18: 0 | AA18: 46114 | AB18: =HYPERLINK("#'Transactions'!A21", "View Source Row")
A19: 21 | B19: 502 input.pdf | C19: 46113 | D19: 46142 | E19: 46114 | F19: 46114 | G19: DIGITA-MUMBAI/ NEFT-KKBKH26092777992-VENKTESHWAR INDUSTRIAL CORPO | I19: Receipt | J19: 0 | K19: 18088 | L19: 18088 | M19: 590917.5 | N19: Recurring Transaction | O19: Yes | P19: VENKTESHWAR INDUSTRIAL CORPO | Q19: 0 | R19: 1 | S19: 0 | T19: 0 | U19: 0 | V19: 0 | W19: 0 | X19: 0 | Y19: 0 | Z19: 0 | AA19: 46114 | AB19: =HYPERLINK("#'Transactions'!A22", "View Source Row")
A20: 23 | B20: 502 input.pdf | C20: 46113 | D20: 46142 | E20: 46114 | F20: 46114 | G20: DIGITA-MUMBAI/ NEFT-NKGSH26092846591-GEBI PRODUCTS PRIVATE LIMITE | I20: Receipt | J20: 0 | K20: 12813 | L20: 12813 | M20: 600930.5 | N20: Recurring Transaction | O20: Yes | P20: GEBI PRODUCTS PRIVATE LIMITE | Q20: 0 | R20: 1 | S20: 0 | T20: 0 | U20: 0 | V20: 0 | W20: 0 | X20: 0 | Y20: 0 | Z20: 0 | AA20: 46114 | AB20: =HYPERLINK("#'Transactions'!A24", "View Source Row")
A21: 24 | B21: 502 input.pdf | C21: 46113 | D21: 46142 | E21: 46114 | F21: 46114 | G21: DIGITA-MUMBAI/ NEFT-IDIBH09236262399-JAI AMBE TRANSPORT | I21: Receipt | J21: 0 | K21: 4378 | L21: 4378 | M21: 605308.5 | N21: Recurring Transaction | O21: Yes | P21: JAI AMBE TRANSPORT | Q21: 0 | R21: 1 | S21: 0 | T21: 0 | U21: 0 | V21: 0 | W21: 0 | X21: 0 | Y21: 0 | Z21: 0 | AA21: 46114 | AB21: =HYPERLINK("#'Transactions'!A25", "View Source Row")
A22: 25 | B22: 502 input.pdf | C22: 46113 | D22: 46142 | E22: 46114 | F22: 46114 | G22: DIGITA-MUMBAI/ NEFT-HDFCH00905140576-Adekar enterprises pvt ltd | I22: Receipt | J22: 0 | K22: 138674 | L22: 138674 | M22: 743982.5 | N22: High Transaction; Recurring Transaction | O22: Yes | P22: ADEKAR ENTERPRISES PVT LTD | Q22: 0 | R22: 1 | S22: 0 | T22: 0 | U22: 1 | V22: 0 | W22: 0 | X22: 0 | Y22: 0 | Z22: 0 | AA22: 46114 | AB22: =HYPERLINK("#'Transactions'!A26", "View Source Row")
A23: 26 | B23: 502 input.pdf | C23: 46113 | D23: 46142 | E23: 46114 | F23: 46114 | G23: DIGITA-MUMBAI/ NEFT-TDCBH26092001785-V C ENTERPRISES | I23: Receipt | J23: 0 | K23: 50000 | L23: 50000 | M23: 793982.5 | N23: Recurring Transaction | O23: Yes | P23: V C ENTERPRISES | Q23: 0 | R23: 1 | S23: 0 | T23: 0 | U23: 0 | V23: 0 | W23: 0 | X23: 0 | Y23: 0 | Z23: 0 | AA23: 46114 | AB23: =HYPERLINK("#'Transactions'!A27", "View Source Row")
A24: 27 | B24: 502 input.pdf | C24: 46113 | D24: 46142 | E24: 46114 | F24: 46114 | G24: EBANK:WIB/1502 EBANK:WIB/1502234210/Edfs | I24: Payment | J24: 791482.5 | K24: 0 | L24: 791482.5 | M24: 2500 | N24: High Transaction; Recurring Transaction | O24: Yes | P24: EBANKWIB | Q24: 0 | R24: 1 | S24: 0 | T24: 0 | U24: 1 | V24: 0 | W24: 0 | X24: 0 | Y24: 0 | Z24: 0 | AA24: 46114 | AB24: =HYPERLINK("#'Transactions'!A28", "View Source Row")
A25: 28 | B25: 502 input.pdf | C25: 46113 | D25: 46142 | E25: 46114 | F25: 46114 | G25: DIGITA-MUMBAI/ ---------------------------------------------------------------------------------------------------------------------------------- Page Total: 7,98,282.50 8,34,458.50 38,676.00Cr ---------------------------------------------------------------------------------------------------------------------------------- Note: Cheques received in inward clearing will be considered for debiting/ returning on the basis opening balance in account Unless the constituent notifies the bank of any di | I25: Receipt | J25: 0 | K25: 36176 | L25: 36176 | M25: 38676 | N25: Recurring Transaction | O25: Yes | P25: PAGE TOTAL CR | Q25: 0 | R25: 1 | S25: 0 | T25: 0 | U25: 0 | V25: 0 | W25: 0 | X25: 0 | Y25: 0 | Z25: 0 | AA25: 46114 | AB25: =HYPERLINK("#'Transactions'!A29", "View Source Row")
A26: 29 | B26: 502 input.pdf | C26: 46113 | D26: 46142 | E26: 46114 | F26: 46114 | G26: DIGITA-MUMBAI/ NEFT-KKBKH26092921670-ATLAS COMMODITIES PRIVATE LI | I26: Receipt | J26: 0 | K26: 4353 | L26: 4353 | M26: 43029 | N26: Recurring Transaction | O26: Yes | P26: ATLAS COMMODITIES PRIVATE LI | Q26: 0 | R26: 1 | S26: 0 | T26: 0 | U26: 0 | V26: 0 | W26: 0 | X26: 0 | Y26: 0 | Z26: 0 | AA26: 46114 | AB26: =HYPERLINK("#'Transactions'!A30", "View Source Row")
A27: 30 | B27: 502 input.pdf | C27: 46113 | D27: 46142 | E27: 46115 | F27: 46115 | G27: DIGITA-MUMBAI/ NEFT-YESAP60934071902-PhonePe Limited | I27: Receipt | J27: 0 | K27: 173393.9 | L27: 173393.9 | M27: 216422.9 | N27: High Transaction; Recurring Transaction | O27: Yes | P27: PHONEPE LIMITED | Q27: 0 | R27: 1 | S27: 0 | T27: 0 | U27: 1 | V27: 0 | W27: 0 | X27: 0 | Y27: 0 | Z27: 0 | AA27: 46115 | AB27: =HYPERLINK("#'Transactions'!A31", "View Source Row")
A28: 31 | B28: 502 input.pdf | C28: 46113 | D28: 46142 | E28: 46115 | F28: 46115 | G28: DIGITA-MUMBAI/ NEFT-AXNPN09311160907-PHONEPE LIMITED-PAYMENT AGGR | I28: Receipt | J28: 0 | K28: 53957.68 | L28: 53957.68 | M28: 270380.58 | N28: Recurring Transaction | O28: Yes | P28: PHONEPE LIMITED | Q28: 0 | R28: 1 | S28: 0 | T28: 0 | U28: 0 | V28: 0 | W28: 0 | X28: 0 | Y28: 0 | Z28: 0 | AA28: 46115 | AB28: =HYPERLINK("#'Transactions'!A32", "View Source Row")
A29: 32 | B29: 502 input.pdf | C29: 46113 | D29: 46142 | E29: 46115 | F29: 46115 | G29: DIGITA-MUMBAI/ NEFT-AXISCN1300289999-ONE MOBIKWIK SYSTEMS LIMITED | I29: Receipt | J29: 0 | K29: 21700 | L29: 21700 | M29: 292080.58 | N29: Recurring Transaction | O29: Yes | P29: ONE MOBIKWIK SYSTEMS LIMITED | Q29: 0 | R29: 1 | S29: 0 | T29: 0 | U29: 0 | V29: 0 | W29: 0 | X29: 0 | Y29: 0 | Z29: 0 | AA29: 46115 | AB29: =HYPERLINK("#'Transactions'!A33", "View Source Row")
A30: 33 | B30: 502 input.pdf | C30: 46113 | D30: 46142 | E30: 46115 | F30: 46115 | G30: DIGITA-MUMBAI/ IMPS/P2A/609308206742/S TRANS 14851/Mh04ju3738I | I30: Receipt | J30: 0 | K30: 5750 | L30: 5750 | M30: 297830.58 | N30: Recurring Transaction | O30: Yes | P30: DIGITA-MUMBAI/ IMPS/P#A/#/S TRANS #/MH#JU#I | Q30: 0 | R30: 1 | S30: 0 | T30: 0 | U30: 0 | V30: 0 | W30: 0 | X30: 0 | Y30: 0 | Z30: 0 | AA30: 46115 | AB30: =HYPERLINK("#'Transactions'!A34", "View Source Row")
A31: 34 | B31: 502 input.pdf | C31: 46113 | D31: 46142 | E31: 46115 | F31: 46115 | G31: DIGITA-MUMBAI/ NEFT-AXISCN1300388689-PINE LABS PRIVATE LIMITED-NO | I31: Receipt | J31: 0 | K31: 112894 | L31: 112894 | M31: 410724.58 | N31: High Transaction; Recurring Transaction | O31: Yes | P31: PINE LABS PRIVATE LIMITED | Q31: 0 | R31: 1 | S31: 0 | T31: 0 | U31: 1 | V31: 0 | W31: 0 | X31: 0 | Y31: 0 | Z31: 0 | AA31: 46115 | AB31: =HYPERLINK("#'Transactions'!A35", "View Source Row")
A32: 35 | B32: 502 input.pdf | C32: 46113 | D32: 46142 | E32: 46115 | F32: 46115 | G32: DIGITA-MUMBAI/ IMPS/P2A/609312855509/AFZALSIRAJUDDIN/IMPSUOB9191 | I32: Receipt | J32: 0 | K32: 200000 | L32: 200000 | M32: 610724.58 | N32: High Transaction; Recurring Transaction | O32: Yes | P32: AFZALSIRAJUDDIN | Q32: 0 | R32: 1 | S32: 0 | T32: 0 | U32: 1 | V32: 0 | W32: 0 | X32: 0 | Y32: 0 | Z32: 0 | AA32: 46115 | AB32: =HYPERLINK("#'Transactions'!A36", "View Source Row")
A33: 37 | B33: 502 input.pdf | C33: 46113 | D33: 46142 | E33: 46115 | F33: 46115 | G33: EBANK:WIB/1502 EBANK:WIB/1502413595/Edfs | I33: Payment | J33: 790104.58 | K33: 0 | L33: 790104.58 | M33: 1500 | N33: High Transaction; Recurring Transaction | O33: Yes | P33: EBANKWIB | Q33: 0 | R33: 1 | S33: 0 | T33: 0 | U33: 1 | V33: 0 | W33: 0 | X33: 0 | Y33: 0 | Z33: 0 | AA33: 46115 | AB33: =HYPERLINK("#'Transactions'!A38", "View Source Row")
A34: 38 | B34: 502 input.pdf | C34: 46113 | D34: 46142 | E34: 46116 | F34: 46116 | G34: DIGITA-MUMBAI/ NEFT-YESAP60944128518-PhonePe Limited | I34: Receipt | J34: 0 | K34: 171014 | L34: 171014 | M34: 172514 | N34: High Transaction; Recurring Transaction | O34: Yes | P34: PHONEPE LIMITED | Q34: 0 | R34: 1 | S34: 0 | T34: 0 | U34: 1 | V34: 0 | W34: 0 | X34: 0 | Y34: 0 | Z34: 0 | AA34: 46116 | AB34: =HYPERLINK("#'Transactions'!A39", "View Source Row")
A35: 39 | B35: 502 input.pdf | C35: 46113 | D35: 46142 | E35: 46116 | F35: 46116 | G35: DIGITA-MUMBAI/ https://cbdrpt101.bankofbaroda.co.in:22000/finbranch/arjspmorph/INFENG/tran_rpt.jsp?... 04-05-2026 NEFT-AXNPN09418938602-PHONEPE LIMITED-PAYMENT AGGR | I35: Receipt | J35: 0 | K35: 49956 | L35: 49956 | M35: 222470 | N35: Recurring Transaction | O35: Yes | P35: CBDRPTBANKOFBARODACOIN | Q35: 0 | R35: 1 | S35: 0 | T35: 0 | U35: 0 | V35: 0 | W35: 0 | X35: 0 | Y35: 0 | Z35: 0 | AA35: 46116 | AB35: =HYPERLINK("#'Transactions'!A40", "View Source Row")
A36: 40 | B36: 502 input.pdf | C36: 46113 | D36: 46142 | E36: 46116 | F36: 46116 | G36: DIGITA-MUMBAI/ NEFT-AXISCN1301100257-ONE MOBIKWIK SYSTEMS LIMITED | I36: Receipt | J36: 0 | K36: 22121 | L36: 22121 | M36: 244591 | N36: Recurring Transaction | O36: Yes | P36: ONE MOBIKWIK SYSTEMS LIMITED | Q36: 0 | R36: 1 | S36: 0 | T36: 0 | U36: 0 | V36: 0 | W36: 0 | X36: 0 | Y36: 0 | Z36: 0 | AA36: 46116 | AB36: =HYPERLINK("#'Transactions'!A41", "View Source Row")
A37: 41 | B37: 502 input.pdf | C37: 46113 | D37: 46142 | E37: 46116 | F37: 46116 | G37: EBANK:WIB/1502 EBANK:WIB/1502423934/Edfs | I37: Payment | J37: 240091 | K37: 0 | L37: 240091 | M37: 4500 | N37: High Transaction; Recurring Transaction | O37: Yes | P37: EBANKWIB | Q37: 0 | R37: 1 | S37: 0 | T37: 0 | U37: 1 | V37: 0 | W37: 0 | X37: 0 | Y37: 0 | Z37: 0 | AA37: 46116 | AB37: =HYPERLINK("#'Transactions'!A42", "View Source Row")
A38: 42 | B38: 502 input.pdf | C38: 46113 | D38: 46142 | E38: 46116 | F38: 46116 | G38: DIGITA-MUMBAI/ NEFT-AXISCN1301297166-PINE LABS PRIVATE LIMITED-NO | I38: Receipt | J38: 0 | K38: 22400 | L38: 22400 | M38: 26900 | N38: Recurring Transaction | O38: Yes | P38: PINE LABS PRIVATE LIMITED | Q38: 0 | R38: 1 | S38: 0 | T38: 0 | U38: 0 | V38: 0 | W38: 0 | X38: 0 | Y38: 0 | Z38: 0 | AA38: 46116 | AB38: =HYPERLINK("#'Transactions'!A43", "View Source Row")
A39: 43 | B39: 502 input.pdf | C39: 46113 | D39: 46142 | E39: 46116 | F39: 46116 | G39: DIGITA-MUMBAI/ NEFT-HDFCH00909652553-KUNDAN QUARRY ---------------------------------------------------------------------------------------------------------------------------------- Page Total: 10,30,195.58 10,24,219.58 32,700.00Cr ---------------------------------------------------------------------------------------------------------------------------------- Note: Cheques received in inward clearing will be considered for debiting/ returning on the basis opening balance in account Unless the c | I39: Receipt | J39: 0 | K39: 5800 | L39: 5800 | M39: 32700 | N39: Recurring Transaction | O39: Yes | P39: KUNDAN QUARRY | Q39: 0 | R39: 1 | S39: 0 | T39: 0 | U39: 0 | V39: 0 | W39: 0 | X39: 0 | Y39: 0 | Z39: 0 | AA39: 46116 | AB39: =HYPERLINK("#'Transactions'!A44", "View Source Row")
A40: 45 | B40: 502 input.pdf | C40: 46113 | D40: 46142 | E40: 46116 | F40: 46116 | G40: DIGITA-MUMBAI/ NEFT-KKBKH26094919635-ATLAS COMMODITIES PRIVATE LI | I40: Receipt | J40: 0 | K40: 7885 | L40: 7885 | M40: 40434.37 | N40: Recurring Transaction | O40: Yes | P40: ATLAS COMMODITIES PRIVATE LI | Q40: 0 | R40: 1 | S40: 0 | T40: 0 | U40: 0 | V40: 0 | W40: 0 | X40: 0 | Y40: 0 | Z40: 0 | AA40: 46116 | AB40: =HYPERLINK("#'Transactions'!A46", "View Source Row")
A41: 47 | B41: 502 input.pdf | C41: 46113 | D41: 46142 | E41: 46116 | F41: 46116 | G41: EBANK:WIB/1502 EBANK:WIB/1502545632/Edfs | I41: Payment | J41: 120330.37 | K41: 0 | L41: 120330.37 | M41: 1500 | N41: High Transaction; Recurring Transaction | O41: Yes | P41: EBANKWIB | Q41: 0 | R41: 1 | S41: 0 | T41: 0 | U41: 1 | V41: 0 | W41: 0 | X41: 0 | Y41: 0 | Z41: 0 | AA41: 46116 | AB41: =HYPERLINK("#'Transactions'!A48", "View Source Row")
...

Sheet Detail EMI
A1: =HYPERLINK("#'Dashboard'!A1", "← Return to Dashboard") | B1: EMI Transactions
A2: Rows | B2: 2 | C2: Match | D2: EMI
A4: Seq | B4: Source File | C4: Statement From | D4: Statement To | E4: Date | F4: Value Date | G4: Narration | H4: Reference | I4: Direction | J4: Withdrawal | K4: Deposit | L4: Amount | M4: Closing Balance | N4: Categories | O4: Recurring? | P4: Recurring Key | Q4: Flag - Cash | R4: Flag - Recurring Transaction | S4: Flag - EMI | T4: Flag - Salary | U4: Flag - High Transaction | V4: Flag - UPI | W4: Flag - LIC | X4: Flag - FD interest | Y4: Flag - FD Deposit and withdrawals | Z4: Flag - PPF/PF interest and contribution | AA4: Month Date | AB4: View Source Row
A5: 7 | B5: 502 input.pdf | C5: 46113 | D5: 46142 | E5: 46114 | F5: 46114 | G5: DIGITA-MUMBAI/ NEFT-FBPT260916108327-PREMIER CONVEYORS PRIVATE LI | I5: Receipt | J5: 0 | K5: 18409 | L5: 18409 | M5: 20909 | N5: EMI; Recurring Transaction | O5: Yes | P5: PREMIER CONVEYORS PRIVATE LI | Q5: 0 | R5: 1 | S5: 1 | T5: 0 | U5: 0 | V5: 0 | W5: 0 | X5: 0 | Y5: 0 | Z5: 0 | AA5: 46114 | AB5: =HYPERLINK("#'Transactions'!A8", "View Source Row")
A6: 226 | B6: 502 input.pdf | C6: 46113 | D6: 46142 | E6: 46130 | F6: 46130 | G6: DIGITA-MUMBAI/ NEFT-FBPT261087153653-PREMIER CONVEYORS PRIVATE LI | I6: Receipt | J6: 0 | K6: 37132 | L6: 37132 | M6: 483167.28 | N6: EMI; Recurring Transaction | O6: Yes | P6: PREMIER CONVEYORS PRIVATE LI | Q6: 0 | R6: 1 | S6: 1 | T6: 0 | U6: 0 | V6: 0 | W6: 0 | X6: 0 | Y6: 0 | Z6: 0 | AA6: 46130 | AB6: =HYPERLINK("#'Transactions'!A227", "View Source Row")

Sheet Detail Salary
A1: =HYPERLINK("#'Dashboard'!A1", "← Return to Dashboard") | B1: Salary Transactions
A2: Rows | B2: 0 | C2: Match | D2: Salary
A4: Seq | B4: Source File | C4: Statement From | D4: Statement To | E4: Date | F4: Value Date | G4: Narration | H4: Reference | I4: Direction | J4: Withdrawal | K4: Deposit | L4: Amount | M4: Closing Balance | N4: Categories | O4: Recurring? | P4: Recurring Key | Q4: Flag - Cash | R4: Flag - Recurring Transaction | S4: Flag - EMI | T4: Flag - Salary | U4: Flag - High Transaction | V4: Flag - UPI | W4: Flag - LIC | X4: Flag - FD interest | Y4: Flag - FD Deposit and withdrawals | Z4: Flag - PPF/PF interest and contribution | AA4: Month Date | AB4: View Source Row
A5: No matching transactions.

Sheet Detail High Transaction
A1: =HYPERLINK("#'Dashboard'!A1", "← Return to Dashboard") | B1: High Transaction Transactions
A2: Rows | B2: 112 | C2: Match | D2: High Transaction
A4: Seq | B4: Source File | C4: Statement From | D4: Statement To | E4: Date | F4: Value Date | G4: Narration | H4: Reference | I4: Direction | J4: Withdrawal | K4: Deposit | L4: Amount | M4: Closing Balance | N4: Categories | O4: Recurring? | P4: Recurring Key | Q4: Flag - Cash | R4: Flag - Recurring Transaction | S4: Flag - EMI | T4: Flag - Salary | U4: Flag - High Transaction | V4: Flag - UPI | W4: Flag - LIC | X4: Flag - FD interest | Y4: Flag - FD Deposit and withdrawals | Z4: Flag - PPF/PF interest and contribution | AA4: Month Date | AB4: View Source Row
A5: 2 | B5: 502 input.pdf | C5: 46113 | D5: 46142 | E5: 46114 | F5: 46114 | G5: DIGITA-MUMBAI/ NEFT-YESAP60912594024-PhonePe Limited | I5: Receipt | J5: 0 | K5: 165179 | L5: 165179 | M5: 581570 | N5: High Transaction; Recurring Transaction | O5: Yes | P5: PHONEPE LIMITED | Q5: 0 | R5: 1 | S5: 0 | T5: 0 | U5: 1 | V5: 0 | W5: 0 | X5: 0 | Y5: 0 | Z5: 0 | AA5: 46114 | AB5: =HYPERLINK("#'Transactions'!A3", "View Source Row")
A6: 6 | B6: 502 input.pdf | C6: 46113 | D6: 46142 | E6: 46114 | F6: 46114 | G6: EBANK:WIB/1502 EBANK:WIB/1502021829/Edfs | I6: Payment | J6: 681881.6 | K6: 0 | L6: 681881.6 | M6: 2500 | N6: High Transaction; Recurring Transaction | O6: Yes | P6: EBANKWIB | Q6: 0 | R6: 1 | S6: 0 | T6: 0 | U6: 1 | V6: 0 | W6: 0 | X6: 0 | Y6: 0 | Z6: 0 | AA6: 46114 | AB6: =HYPERLINK("#'Transactions'!A7", "View Source Row")
A7: 8 | B7: 502 input.pdf | C7: 46113 | D7: 46142 | E7: 46114 | F7: 46114 | G7: DIGITA-MUMBAI/ NEFT-CNRBH00121803213-QUALITY PLAST INDUSTRIES LIM | I7: Receipt | J7: 0 | K7: 121431 | L7: 121431 | M7: 142340 | N7: High Transaction; Recurring Transaction | O7: Yes | P7: QUALITY PLAST INDUSTRIES LIM | Q7: 0 | R7: 1 | S7: 0 | T7: 0 | U7: 1 | V7: 0 | W7: 0 | X7: 0 | Y7: 0 | Z7: 0 | AA7: 46114 | AB7: =HYPERLINK("#'Transactions'!A9", "View Source Row")
